Workbook

Sheet Setup
A1: Forge — test setup
A3: How to use this workbook
A4: 1 | B4: Do the steps in "Start the app" and fill in "Test data" (yellow cells).
A5: 2 | B5: Work through "Test cases" in order — later cases rely on earlier ones (see Preconditions).
A6: 3 | B6: Set Status for each case: Pass / Fail / Blocked / Not run. On Fail, write what you saw in "Notes / defect".
A7: 4 | B7: Example of a filled-in failure: Status = Fail, Notes = "Step 3: got HTTP 500 instead of the Pick tools card".
A8: 5 | B8: P1 = core flow and safety rules (must pass before a demo). P2 = everything else.
A9: 6 | B9: {GITHUB_REPO}, {SLACK_CHANNEL_ID} etc. in the steps mean: use the value from "Test data" below.
A10: 7 | B10: "Summary" counts results automatically.
A12: Start the app
A13: 1. Docker | B13: Start Docker Desktop and wait until it says it is running.
A14: 2. Clean start (optional, deletes ALL data) | B14: In the project folder: docker compose down -v then docker compose up -d --build
A15: 3. Start (keep data) | B15: docker compose up -d --build
A16: 4. Check | B16: http://localhost:8000/health shows {"ok":true}; http://localhost:5173 shows the sign-in page.
A17: 5. If the build says docker-credential-desktop not found | B17: Open a NEW terminal and run step 3 again.
A18: pgAdmin | B18: http://localhost:5050 — login admin@forge.dev / admin; server "forge" password: forge
A20: Accounts (created during ACC tests; password Passw0rd! for all)
A21: Role | B21: Email | C21: Notes
A22: Platform admin | B22: admin@forge.dev | C22: Exists from the start (.env PLATFORM_ADMIN_PASSWORD, default Passw0rd!)
A23: Company A admin | B23: shivani@northwind.example | C23: Company "Northwind Labs" (schema t_northwind_labs)
A24: Company A user | B24: priya@northwind.example | C24: Joins Northwind Labs
A25: Company B admin | B25: jai@maven.example | C25: Company "Maven" (schema t_maven)
A26: Company B user | B26: riya@maven.example | C26: Joins Maven
A28: Test data (fill in the yellow cells; never commit this file with real tokens in it)
A29: Name | B29: Value | C29: What it is
A30: GITHUB_PAT | C30: GitHub personal access token with Issues + Contents access
A31: GITHUB_REPO | C31: owner/repo with at least 2 open issues, one labelled bug
A32: SLACK_TOKEN | C32: Slack USER token xoxp-… (bot tokens xoxb- are rejected)
A33: SLACK_CHANNEL_ID | C33: Channel ID C0… that the Slack app is a member of
A34: TAVILY_KEY | C34: tvly-… from app.tavily.com (optional, REG-17)
A35: WRONG_TOKEN | B35: ghp_invalid0000000000000000000000000000 | C35: Any token that will be refused

Sheet Test cases
A1: ID | B1: Area | C1: Title | D1: Role / account | E1: Preconditions | F1: Steps | G1: Expected result | H1: DB check (optional SQL) | I1: Priority | J1: Status | K1: Notes / defect
A2: ACC-01 | B2: Accounts & sign-in | C2: Platform admin signs in | D2: Platform admin (admin@forge.dev) | E2: Fresh database (Setup step 2). | F2: 1. Open http://localhost:5173. 2. On the "Sign in" tab enter Email admin@forge.dev and Password Passw0rd! (or PLATFORM_ADMIN_PASSWORD from .env). 3. Click "Sign in". | G2: Lands on MCP Registry. Sidebar shows only the "Shared" section: MCP Registry, Marketplace, Admin Review. Footer reads "Platform admin". No Build, My Agents or Connections. | H2: SELECT email, role FROM platform.users; -- admin@forge.dev | platform_admin | I2: P1 | J2: Not run
A3: ACC-02 | B3: Accounts & sign-in | C3: Create a new company makes you its admin | D3: Company A admin (shivani@northwind.example) | E3: ACC-01 passed; signed out. | F3: 1. Click the "Register" tab. 2. Click "Create a new company". 3. Company name (new): Northwind Labs. Your name: Shivani. Email: shivani@northwind.example. Password: Passw0rd! 4. Click "Create company". | G3: Signed in. Footer reads "Northwind Labs · admin". Sidebar "Workspace" section shows Build, My Agents, MCP Registry, Connections. | H3: SELECT t.name, u.email, u.role FROM platform.users u JOIN platform.tenants t ON t.id=u.tenant_id; -- also: a new schema t_northwind_labs exists (pgAdmin → Schemas) | I3: P1 | J3: Not run
A4: ACC-03 | B4: Accounts & sign-in | C4: Join an existing company makes you a user | D4: Company A user (priya@northwind.example) | E4: ACC-02 passed; signed out. | F4: 1. Click "Register" → "Join an existing one". 2. Company name (exactly as your admin created it): Northwind Labs. Your name: Priya. Email: priya@northwind.example. Password: Passw0rd! 3. Click "Join company". | G4: Signed in. Footer reads "Northwind Labs · user". | H4: SELECT email, role FROM platform.users WHERE email='priya@northwind.example'; -- role = user, same tenant as Shivani | I4: P1 | J4: Not run
A5: ACC-04 | B5: Accounts & sign-in | C5: Second company and its user | D5: Company B admin (jai@maven.example) / Company B user (riya@maven.example) | E5: ACC-03 passed. | F5: 1. Register → Create a new company: Maven, Jai, jai@maven.example, Passw0rd! → "Create company". Sign out. 2. Register → Join an existing one: Maven, Riya, riya@maven.example, Passw0rd! → "Join company". | G5: Jai's footer: "Maven · admin". Riya's footer: "Maven · user". A schema t_maven exists. | I5: P1 | J5: Not run
A6: ACC-05 | B6: Accounts & sign-in | C6: Joining a company that does not exist is refused | D6: Any | E6: Signed out. | F6: 1. Register → "Join an existing one". 2. Company name: Nowhere Corp; fill the other fields with a new email. 3. Click "Join company". | G6: Message: "No company with that name. Check the spelling with your admin, or create it." No account is created. | H6: SELECT count(*) FROM platform.users WHERE email='<the email you used>'; -- 0 | I6: P1 | J6: Not run
A7: ACC-06 | B7: Accounts & sign-in | C7: Creating a company that already exists is refused | D7: Any | E7: ACC-02 passed; signed out. | F7: 1. Register → "Create a new company". 2. Company name: Northwind Labs; new email. 3. Click "Create company". | G7: Message: "That company already exists. Choose Join to become one of its users." | I7: P1 | J7: Not run
A8: ACC-07 | B8: Accounts & sign-in | C8: An email can only register once | D8: Any | E8: ACC-03 passed; signed out. | F8: 1. Register → Join an existing one → Northwind Labs, email priya@northwind.example. 2. Click "Join company". | G8: Message: "That email already has an account. Sign in instead." | I8: P1 | J8: Not run
A9: ACC-08 | B9: Accounts & sign-in | C9: Wrong password and unknown email give the same message | D9: Any | E9: Signed out. | F9: 1. Sign in as priya@northwind.example with password WrongPass1. 2. Sign in as nobody@nowhere.example with any password. | G9: Both show "That email and password do not match." (it never reveals which addresses exist). | I9: P1 | J9: Not run
A10: ACC-09 | B10: Accounts & sign-in | C10: Password shorter than 8 characters is blocked | D10: Any | E10: Signed out. | F10: 1. Register → Create a new company with password 1234567. 2. Click "Create company". | G10: The browser refuses to submit (minimum 8 characters). No account is created. | I10: P2 | J10: Not run
A11: ACC-10 | B11: Accounts & sign-in | C11: Company name made only of symbols is refused | D11: Any | E11: Signed out. | F11: 1. Register → Create a new company with Company name !!! 2. Click "Create company". | G11: Message: "Use letters and numbers for the company name." | I11: P2 | J11: Not run
A12: ACC-11 | B12: Accounts & sign-in | C12: Sign out | D12: Company A user (priya@northwind.example) | E12: Signed in. | F12: 1. Click "Sign out" at the bottom of the sidebar. 2. Type http://localhost:5173/agents in the address bar. | G12: Returns to the sign-in page; opening /agents while signed out sends you back to sign-in. | I12: P2 | J12: Not run
A13: ACC-12 | B13: Accounts & sign-in | C13: Old session after a database reset goes back to sign-in | D13: Company A user (priya@northwind.example) | E13: Signed in. You are willing to wipe all data. | F13: 1. In a terminal: docker compose down -v, then docker compose up -d. 2. Reload the browser tab. | G13: You are sent to the sign-in page. No error page or HTTP 500. | I13: P2 | J13: Not run
A14: REG-01 | B14: MCP Registry | C14: Register filesystem with no token | D14: Company A admin (shivani@northwind.example) | E14: Signed in as Shivani. | F14: 1. Click "MCP Registry" → "+ Register a server". 2. In "Register an MCP server" click the chip "filesystem" (Name, Transport stdio and Endpoint fill in). 3. Click "Connect". 4. Check the tool list "Tools agents may use (N found)": tools grouped read / write / destructive, read tools ticked. 5. Click "Save server (N tools)". | G14: A "filesystem" card appears under "Private to Northwind Labs" with "ok" and "just me" badges, a "X of N tools on" chip, and "registered by you". Only the read tools are on. | H14: SELECT s.name, s.visibility, s.health, count(t.id) FILTER (WHERE t.enabled) AS on_, count(t.id) AS total FROM t_northwind_labs.mcp_servers s JOIN t_northwind_labs.mcp_tools t ON t.server_id=s.id GROUP BY 1,2,3; | I14: P1 | J14: Not run
A15: REG-02 | B15: MCP Registry | C15: "Connect" lists tools but saves nothing | D15: Company A admin (shivani@northwind.example) | E15: Signed in as Shivani; no "git" server yet. | F15: 1. Register a server → chip "git" → "Connect". 2. When the tool list appears, click "Cancel". | G15: No "git" card appears. Nothing is stored until "Save server" is clicked. | H15: SELECT count(*) FROM t_northwind_labs.mcp_servers WHERE name='git'; -- 0 | I15: P1 | J15: Not run
A16: REG-03 | B16: MCP Registry | C16: Register GitHub with a valid token | D16: Company A admin (shivani@northwind.example) | E16: Signed in as Shivani. GITHUB_PAT ready. | F16: 1. Register a server → chip "github". 2. Paste GITHUB_PAT into "Credential". 3. Click "Connect" (about 40+ tools appear). 4. Tick "issue_write" as well as the pre-ticked read tools. 5. Click "Save server". | G16: A "github" card with a "connected" badge (the token became Shivani's own encrypted connection). Connections page lists github as active. | H16: SELECT server_name, status, length(encrypted_secret) AS bytes FROM t_northwind_labs.connections; | I16: P1 | J16: Not run
A17: REG-04 | B17: MCP Registry | C17: GitHub with no token is refused | D17: Company A user (priya@northwind.example) | E17: Signed in as Priya. | F17: 1. Register a server → chip "github". 2. Leave "Credential" empty. 3. Click "Connect". | G17: Message: "Nothing was saved. github answered but will not list its tools without a credential. Paste one and try again." | I17: P1 | J17: Not run
A18: REG-05 | B18: MCP Registry | C18: GitHub with a wrong token is refused | D18: Company A user (priya@northwind.example) | E18: Signed in as Priya. | F18: 1. Register a server → chip "github". 2. Paste WRONG_TOKEN into "Credential". 3. Click "Connect". | G18: Message starts "Nothing was saved. github rejected that credential." No card, no connection. | I18: P1 | J18: Not run
A19: REG-06 | B19: MCP Registry | C19: A user cannot switch on destructive tools | D19: Company A user (priya@northwind.example) | E19: Signed in as Priya. GITHUB_PAT ready. | F19: 1. Register a server → chip "github" → paste GITHUB_PAT → "Connect". 2. Find the "destructive" group in the tool list (e.g. delete_file). 3. Try to tick it. Hover over it. 4. Click "all" in the list header. 5. Click "Save server". | G19: Destructive tools are greyed out and cannot be ticked; hover reads "Only an admin can enable destructive tools". A line says "1 destructive tool can only be enabled by an admin." "all" ticks everything EXCEPT them. The saved card shows no destructive tool switched on. | H19: SELECT t.name, t.risk, t.enabled FROM <priya's schema>.mcp_tools t WHERE t.risk='destructive'; -- enabled = false | I19: P1 | J19: Not run
A20: REG-07 | B20: MCP Registry | C20: An admin can switch on a destructive tool | D20: Company A admin (shivani@northwind.example) | E20: REG-03 passed. | F20: 1. On Shivani's github card click "Edit". 2. Tick delete_file in the tool list. 3. Click "Save changes". | G20: Back on the registry, the github card shows "1 destructive". (Write and destructive tools still ask for approval on every call.) | I20: P2 | J20: Not run
A21: REG-08 | B21: MCP Registry | C21: Registering a name that is already taken is refused | D21: Company A admin (shivani@northwind.example) | E21: REG-03 passed. | F21: 1. Register a server → chip "github" → paste GITHUB_PAT → "Connect" → "Save server". | G21: Message: "Nothing was saved. github is already registered. To change it, use Edit on its card above." The existing card is unchanged. | I21: P1 | J21: Not run
A22: REG-09 | B22: MCP Registry | C22: "Visible to" options depend on role | D22: Company A user (priya@northwind.example) / Company A admin (shivani@northwind.example) / Platform admin (admin@forge.dev) | E22: None. | F22: 1. As Priya open the register form and open "Visible to". 2. Repeat as Shivani. 3. Repeat as admin@forge.dev. | G22: Priya: "Just my workspace" and a disabled "Everyone (admin only)". Shivani: also "My whole company". Platform admin: only "Everyone (admin only)". | I22: P2 | J22: Not run
A23: REG-10 | B23: MCP Registry | C23: Company admin shares a server with the company | D23: Company A admin (shivani@northwind.example) then Company A user (priya@northwind.example) | E23: REG-03 passed. | F23: 1. As Shivani, on the github card click "share with company". 2. Sign in as Priya and open MCP Registry. | G23: Shivani's card shows "whole company". Priya sees the github card with "registered by shivani@northwind.example" and a "Connect" button (she must connect her OWN token). | H23: SELECT name, visibility FROM t_northwind_labs.mcp_servers; -- github | company | I23: P1 | J23: Not run
A24: REG-11 | B24: MCP Registry | C24: "make private" takes the server back | D24: Company A admin (shivani@northwind.example) then Company A user (priya@northwind.example) | E24: REG-10 passed. | F24: 1. As Shivani click "make private" on the github card. 2. Sign in as Priya and open MCP Registry. 3. Afterwards, click "share with company" again (later tests need it shared). | G24: Priya no longer sees Shivani's github card while it is private. | I24: P2 | J24: Not run
A25: REG-12 | B25: MCP Registry | C25: A user has no Edit / Delete on any card | D25: Company A user (priya@northwind.example) | E25: REG-10 passed. | F25: 1. As Priya look at every card in MCP Registry, including any she registered herself. | G25: No "Edit" or "Delete" buttons and no share links appear for a user. Only admins edit or delete, and only servers they own. | I25: P2 | J25: Not run
A26: REG-13 | B26: MCP Registry | C26: Edit the description (no network needed) | D26: Company A admin (shivani@northwind.example) | E26: REG-01 passed. | F26: 1. On the filesystem card click "Edit" (page "Edit filesystem"). 2. Change "Description" to "Test edit". 3. Click "Save changes". | G26: Back on the registry the card shows the new description. Tools and health are unchanged. | I26: P2 | J26: Not run
A27: REG-14 | B27: MCP Registry | C27: Edit to a broken endpoint saves nothing | D27: Company A admin (shivani@northwind.example) | E27: REG-01 passed. | F27: 1. On the filesystem card click "Edit". 2. Change "Endpoint" to definitely-not-a-real-binary. 3. Click "Save changes". | G27: Message starts "Nothing was saved." The card keeps its old endpoint. | I27: P2 | J27: Not run
A28: REG-15 | B28: MCP Registry | C28: Platform admin shares a server with every company | D28: Platform admin (admin@forge.dev) then Company A user (priya@northwind.example) and Company B user (riya@maven.example) | E28: SLACK_TOKEN ready. | F28: 1. As admin@forge.dev: + Register a server → chip "slack" → paste SLACK_TOKEN → "Connect". 2. Tick the read tools plus the tool that posts a message (e.g. a send/post message tool) → "Save server". 3. Sign in as Priya, then as Riya, and open MCP Registry. | G28: Both companies see "slack" under "Shared servers" with a "Connect" button. The platform admin's token was used once for discovery and is NOT stored. | H28: SELECT name FROM platform.mcp_servers; -- slack SELECT count(*) FROM t_northwind_labs.connections WHERE server_name='slack'; -- 0 until Priya connects | I28: P1 | J28: Not run
A29: REG-16 | B29: MCP Registry | C29: Re-check refreshes the server | D29: Company A admin (shivani@northwind.example) | E29: REG-01 passed. | F29: 1. On the filesystem card click "re-check". | G29: The link shows "working…" then the card reads "checked just now" with health "ok". | I29: P2 | J29: Not run
A30: REG-17 | B30: MCP Registry | C30: Register Tavily (web search) | D30: Company A admin (shivani@northwind.example) | E30: TAVILY_KEY ready. | F30: 1. + Register a server → chip "tavily" → paste TAVILY_KEY → "Connect" → "Save server". | G30: A "tavily" card appears, "connected", with search/extract tools. | I30: P2 | J30: Not run
A31: REG-18 | B31: MCP Registry | C31: Delete a server you own | D31: Company A admin (shivani@northwind.example) | E31: A spare server exists (e.g. register "sqlite" via its chip first). | F31: 1. On the sqlite card click "Delete". 2. Read the confirmation, then confirm. | G31: The card disappears. Saved connections are kept. Agents that used it lose those tools. | H31: SELECT count(*) FROM t_northwind_labs.mcp_servers WHERE name='sqlite'; -- 0 | I31: P2 | J31: Not run
A32: REG-19 | B32: MCP Registry | C32: Health sweep marks a dead server "down" (optional) | D32: Company A admin (shivani@northwind.example) | E32: You can stop a server you registered (e.g. your own local MCP server over http). | F32: 1. Register your own http MCP server. 2. Stop that server. 3. Wait 5 minutes (sweep interval) or click "re-check". | G32: The card's health changes to "down". Agents that use it report the server as unavailable. | I32: P2 | J32: Not run
A33: CON-01 | B33: Connections | C33: Add a connection with a valid token | D33: Company A user (priya@northwind.example) | E33: REG-15 passed (slack shared). SLACK_TOKEN ready. | F33: 1. Click "Connections" → "+ Add a connection". 2. Server: slack. Credential: paste SLACK_TOKEN. 3. Click "Save connection". | G33: The button shows "Checking…", then a row: slack · active · Secret shown as dots · Added by priya@northwind.example. The token is never displayed again. | H33: SELECT server_name, status, added_by, length(encrypted_secret) AS bytes FROM t_northwind_labs.connections; | I33: P1 | J33: Not run
A34: CON-02 | B34: Connections | C34: A wrong token is checked and refused | D34: Company A user (priya@northwind.example) | E34: slack not yet connected for Priya. | F34: 1. Connections → "+ Add a connection" → Server: slack → paste WRONG_TOKEN → "Save connection". | G34: Message starts "Nothing was saved." No row is added. | I34: P1 | J34: Not run
A35: CON-03 | B35: Connections | C35: Connect GitHub for the user | D35: Company A user (priya@northwind.example) | E35: REG-10 passed (github shared). GITHUB_PAT ready. | F35: 1. MCP Registry → on the github card click "Connect" (opens Connections). 2. Paste GITHUB_PAT → "Save connection". | G35: github row is active for Priya. Back on the registry, the github card shows "connected". | I35: P1 | J35: Not run
A36: CON-04 | B36: Connections | C36: A colleague's connections are invisible | D36: Company A admin (shivani@northwind.example) | E36: CON-01 passed. | F36: 1. Sign in as Shivani and open Connections. | G36: Shivani sees only her own rows, never Priya's slack connection. | I36: P1 | J36: Not run
A37: CON-05 | B37: Connections | C37: Revoke and reconnect | D37: Company A user (priya@northwind.example) | E37: CON-01 passed. | F37: 1. Connections → on the slack row click "Revoke". 2. Click "Reconnect" on the revoked row. 3. Paste WRONG_TOKEN → "Reconnect". 4. Paste SLACK_TOKEN → "Reconnect". | G37: After Revoke: status "revoked". Wrong token: "Nothing was saved." and it stays revoked. Right token: back to "active". | H37: SELECT server_name, status, length(encrypted_secret) FROM t_northwind_labs.connections; -- revoked rows have 0 bytes | I37: P2 | J37: Not run
A38: BLD-01 | B38: Build | C38: A simple request pauses at "Pick tools" | D38: Company A user (priya@northwind.example) | E38: CON-03 passed (Priya connected to github). | F38: 1. Click "Build". 2. Type: I want an agent that lists the open issues in {GITHUB_REPO} 3. Click "Send". | G38: Card "Paused · waiting for you" with Shape: single agent, a reason, and suggested tools marked "suggested" (e.g. github.list_issues). Builder graph: step 1 ✓, step 2 "Pick tools" current. The URL gains ?thread=build-… | H38: SELECT left(thread_id,60) FROM t_northwind_labs.checkpoint_writes WHERE channel='__interrupt__'; | I38: P1 | J38: Not run
A39: BLD-02 | B39: Build | C39: Finish the build | D39: Company A user (priya@northwind.example) | E39: BLD-01 at the Pick tools pause. | F39: 1. Click "Use these N". | G39: "Built and deployed. It is live in your workspace — try it in the Playground:" with Shape, Tools, Approvals ("none needed" for read-only), Needs, Score. Buttons "Open the Playground" and "My Agents". | H39: SELECT name, status FROM t_northwind_labs.agents; -- status = draft | I39: P1 | J39: Not run
A40: BLD-03 | B40: Build | C40: Read-then-write request is split into specialists | D40: Company A user (priya@northwind.example) | E40: CON-01 and CON-03 passed. | F40: 1. Build → type: Read the open issues in {GITHUB_REPO} and post a 3-line summary to Slack channel {SLACK_CHANNEL_ID} 2. Click "Send". 3. Click "Use these N". | G40: Pause shows Shape: coordinator + two specialists (one gathers, one posts). Finished card lists the Slack post tool under "Approvals". | I40: P1 | J40: Not run
...

Sheet Summary
A1: Area | B1: Cases | C1: P1 | D1: Pass | E1: Fail | F1: Blocked | G1: Not run | H1: % passed
A2: Accounts & sign-in | B2: =COUNTIF('Test cases'!$B$2:$B$85,A2) | C2: =COUNTIFS('Test cases'!$B$2:$B$85,A2,'Test cases'!$I$2:$I$85,"P1") | D2: =COUNTIFS('Test cases'!$B$2:$B$85,$A2,'Test cases'!$J$2:$J$85,"Pass") | E2: =COUNTIFS('Test cases'!$B$2:$B$85,$A2,'Test cases'!$J$2:$J$85,"Fail") | F2: =COUNTIFS('Test cases'!$B$2:$B$85,$A2,'Test cases'!$J$2:$J$85,"Blocked") | G2: =COUNTIFS('Test cases'!$B$2:$B$85,$A2,'Test cases'!$J$2:$J$85,"Not run") | H2: =IFERROR(D2/B2,0)
A3: MCP Registry | B3: =COUNTIF('Test cases'!$B$2:$B$85,A3) | C3: =COUNTIFS('Test cases'!$B$2:$B$85,A3,'Test cases'!$I$2:$I$85,"P1") | D3: =COUNTIFS('Test cases'!$B$2:$B$85,$A3,'Test cases'!$J$2:$J$85,"Pass") | E3: =COUNTIFS('Test cases'!$B$2:$B$85,$A3,'Test cases'!$J$2:$J$85,"Fail") | F3: =COUNTIFS('Test cases'!$B$2:$B$85,$A3,'Test cases'!$J$2:$J$85,"Blocked") | G3: =COUNTIFS('Test cases'!$B$2:$B$85,$A3,'Test cases'!$J$2:$J$85,"Not run") | H3: =IFERROR(D3/B3,0)
A4: Connections | B4: =COUNTIF('Test cases'!$B$2:$B$85,A4) | C4: =COUNTIFS('Test cases'!$B$2:$B$85,A4,'Test cases'!$I$2:$I$85,"P1") | D4: =COUNTIFS('Test cases'!$B$2:$B$85,$A4,'Test cases'!$J$2:$J$85,"Pass") | E4: =COUNTIFS('Test cases'!$B$2:$B$85,$A4,'Test cases'!$J$2:$J$85,"Fail") | F4: =COUNTIFS('Test cases'!$B$2:$B$85,$A4,'Test cases'!$J$2:$J$85,"Blocked") | G4: =COUNTIFS('Test cases'!$B$2:$B$85,$A4,'Test cases'!$J$2:$J$85,"Not run") | H4: =IFERROR(D4/B4,0)
A5: Build | B5: =COUNTIF('Test cases'!$B$2:$B$85,A5) | C5: =COUNTIFS('Test cases'!$B$2:$B$85,A5,'Test cases'!$I$2:$I$85,"P1") | D5: =COUNTIFS('Test cases'!$B$2:$B$85,$A5,'Test cases'!$J$2:$J$85,"Pass") | E5: =COUNTIFS('Test cases'!$B$2:$B$85,$A5,'Test cases'!$J$2:$J$85,"Fail") | F5: =COUNTIFS('Test cases'!$B$2:$B$85,$A5,'Test cases'!$J$2:$J$85,"Blocked") | G5: =COUNTIFS('Test cases'!$B$2:$B$85,$A5,'Test cases'!$J$2:$J$85,"Not run") | H5: =IFERROR(D5/B5,0)
A6: Playground | B6: =COUNTIF('Test cases'!$B$2:$B$85,A6) | C6: =COUNTIFS('Test cases'!$B$2:$B$85,A6,'Test cases'!$I$2:$I$85,"P1") | D6: =COUNTIFS('Test cases'!$B$2:$B$85,$A6,'Test cases'!$J$2:$J$85,"Pass") | E6: =COUNTIFS('Test cases'!$B$2:$B$85,$A6,'Test cases'!$J$2:$J$85,"Fail") | F6: =COUNTIFS('Test cases'!$B$2:$B$85,$A6,'Test cases'!$J$2:$J$85,"Blocked") | G6: =COUNTIFS('Test cases'!$B$2:$B$85,$A6,'Test cases'!$J$2:$J$85,"Not run") | H6: =IFERROR(D6/B6,0)
A7: Agents | B7: =COUNTIF('Test cases'!$B$2:$B$85,A7) | C7: =COUNTIFS('Test cases'!$B$2:$B$85,A7,'Test cases'!$I$2:$I$85,"P1") | D7: =COUNTIFS('Test cases'!$B$2:$B$85,$A7,'Test cases'!$J$2:$J$85,"Pass") | E7: =COUNTIFS('Test cases'!$B$2:$B$85,$A7,'Test cases'!$J$2:$J$85,"Fail") | F7: =COUNTIFS('Test cases'!$B$2:$B$85,$A7,'Test cases'!$J$2:$J$85,"Blocked") | G7: =COUNTIFS('Test cases'!$B$2:$B$85,$A7,'Test cases'!$J$2:$J$85,"Not run") | H7: =IFERROR(D7/B7,0)
A8: Tool allow-list | B8: =COUNTIF('Test cases'!$B$2:$B$85,A8) | C8: =COUNTIFS('Test cases'!$B$2:$B$85,A8,'Test cases'!$I$2:$I$85,"P1") | D8: =COUNTIFS('Test cases'!$B$2:$B$85,$A8,'Test cases'!$J$2:$J$85,"Pass") | E8: =COUNTIFS('Test cases'!$B$2:$B$85,$A8,'Test cases'!$J$2:$J$85,"Fail") | F8: =COUNTIFS('Test cases'!$B$2:$B$85,$A8,'Test cases'!$J$2:$J$85,"Blocked") | G8: =COUNTIFS('Test cases'!$B$2:$B$85,$A8,'Test cases'!$J$2:$J$85,"Not run") | H8: =IFERROR(D8/B8,0)
A9: Publish & review | B9: =COUNTIF('Test cases'!$B$2:$B$85,A9) | C9: =COUNTIFS('Test cases'!$B$2:$B$85,A9,'Test cases'!$I$2:$I$85,"P1") | D9: =COUNTIFS('Test cases'!$B$2:$B$85,$A9,'Test cases'!$J$2:$J$85,"Pass") | E9: =COUNTIFS('Test cases'!$B$2:$B$85,$A9,'Test cases'!$J$2:$J$85,"Fail") | F9: =COUNTIFS('Test cases'!$B$2:$B$85,$A9,'Test cases'!$J$2:$J$85,"Blocked") | G9: =COUNTIFS('Test cases'!$B$2:$B$85,$A9,'Test cases'!$J$2:$J$85,"Not run") | H9: =IFERROR(D9/B9,0)
A10: Marketplace | B10: =COUNTIF('Test cases'!$B$2:$B$85,A10) | C10: =COUNTIFS('Test cases'!$B$2:$B$85,A10,'Test cases'!$I$2:$I$85,"P1") | D10: =COUNTIFS('Test cases'!$B$2:$B$85,$A10,'Test cases'!$J$2:$J$85,"Pass") | E10: =COUNTIFS('Test cases'!$B$2:$B$85,$A10,'Test cases'!$J$2:$J$85,"Fail") | F10: =COUNTIFS('Test cases'!$B$2:$B$85,$A10,'Test cases'!$J$2:$J$85,"Blocked") | G10: =COUNTIFS('Test cases'!$B$2:$B$85,$A10,'Test cases'!$J$2:$J$85,"Not run") | H10: =IFERROR(D10/B10,0)
A11: API | B11: =COUNTIF('Test cases'!$B$2:$B$85,A11) | C11: =COUNTIFS('Test cases'!$B$2:$B$85,A11,'Test cases'!$I$2:$I$85,"P1") | D11: =COUNTIFS('Test cases'!$B$2:$B$85,$A11,'Test cases'!$J$2:$J$85,"Pass") | E11: =COUNTIFS('Test cases'!$B$2:$B$85,$A11,'Test cases'!$J$2:$J$85,"Fail") | F11: =COUNTIFS('Test cases'!$B$2:$B$85,$A11,'Test cases'!$J$2:$J$85,"Blocked") | G11: =COUNTIFS('Test cases'!$B$2:$B$85,$A11,'Test cases'!$J$2:$J$85,"Not run") | H11: =IFERROR(D11/B11,0)
A12: Security & isolation | B12: =COUNTIF('Test cases'!$B$2:$B$85,A12) | C12: =COUNTIFS('Test cases'!$B$2:$B$85,A12,'Test cases'!$I$2:$I$85,"P1") | D12: =COUNTIFS('Test cases'!$B$2:$B$85,$A12,'Test cases'!$J$2:$J$85,"Pass") | E12: =COUNTIFS('Test cases'!$B$2:$B$85,$A12,'Test cases'!$J$2:$J$85,"Fail") | F12: =COUNTIFS('Test cases'!$B$2:$B$85,$A12,'Test cases'!$J$2:$J$85,"Blocked") | G12: =COUNTIFS('Test cases'!$B$2:$B$85,$A12,'Test cases'!$J$2:$J$85,"Not run") | H12: =IFERROR(D12/B12,0)
A13: Total | B13: =SUM(B2:B12) | C13: =SUM(C2:C12) | D13: =SUM(D2:D12) | E13: =SUM(E2:E12) | F13: =SUM(F2:F12) | G13: =SUM(G2:G12) | H13: =IFERROR(D13/B13,0)
A15: P1 cases passed | B15: =COUNTIFS('Test cases'!$I$2:$I$85,"P1",'Test cases'!$J$2:$J$85,"Pass") | C15: =COUNTIF('Test cases'!$I$2:$I$85,"P1") | D15: =IFERROR(B15/C15,0)
A16: Ready to demo? (all P1 passed) | B16: =IF(B15=C15,"YES","NO")

Sheet Demo script
A1: # | B1: Say (talk track) | C1: Click / type | D1: You should see | E1: If it goes wrong
A2: Before | B2: — | C2: Day before: run every P1 case in BLD, PLY. Pre-build ONE backup agent (BLD-03) with an approved 👍 run. Use a paid or fresh Gemini key (free tier ≈ 20 AI calls/day). Record a clean run as a video. | D2: Summary sheet says "Ready to demo? YES". | E2: Fix or drop the failing step from the demo.
A3: 1 | B3: "Here's Priya. She's not a developer. Her team uses GitHub and Slack." | C3: Signed in as priya@northwind.example. Show MCP Registry: github and slack cards, both "connected". | D3: Cards with read / write badges. | E3: If a card is "down", click "re-check".
A4: 2 | B4: "She just says what she wants, in plain English." | C4: Build → type: Read the open issues in {GITHUB_REPO} and post a 3-line summary to Slack channel {SLACK_CHANNEL_ID} → Send. | D4: "Paused · waiting for you": a coordinator with two helpers, suggested tools. | E4: If it errors (AI quota), switch to the backup agent: My Agents → open it.
A5: 3 | B5: "It picked only the tools it needs, and it's asking her to confirm." | C5: Click "Use these N". | D5: "Built and deployed." Approvals lists the Slack post tool. | E5: If "Paused · missing credential": paste the Slack token right there → "Connect slack" (a nice moment to show).
A6: 4 | B6: "Now let's try it." | C6: "Open the Playground" → type: Summarise the open issues and post 3 lines to Slack channel {SLACK_CHANNEL_ID} → Send. | D6: Live lines: reading issues… then "a human will be asked first". | E6: If slow, narrate the live lines; it's reading real GitHub.
A7: 5 | B7: "This is the important part. Before it changes anything, it stops and asks. The AI can't skip this." | C7: Point at "Waiting for approval": the exact message and channel. | D7: Approve / Reject card; "nothing runs until you click". | E7: If no card appears, show the backup agent's Runs tab.
A8: 6 | B8: "She approves — and there it is." | C8: Click "Approve". Switch to Slack. | D8: The summary message in the channel. | E8: Show the recorded video.
A9: 7 | B9: "She rates it, which builds a quality score. Good agents can be shared with other companies — scrubbed first." | C9: Click 👍. Settings → "show exactly what will leave". | D9: Listing JSON with [email removed] / "the publisher" placeholders. | E9: Skip if short on time.
